Workbook

Sheet Informe
B9: INFORME MENSUAL DE LOS SERVICIOS DE RECOGIDA DE RESIDUOS
B11: Fecha | D11: 43374
B12: Temporada | D12: Media
B13: Responsable técnico | D13: Eliseo Castell Marín
B16: 1. Recogida de residuos urbanos
C18: Equipos utilizados | D18: Ruta | E18: Horario | F18: Kg recogidos | G18: Incidencias
C20: 7809JZX | D20: 1 | E20: Noche | F20: =GETPIVOTDATA("Carga",RSU!$A$1,"Matrícula","7809JZX","Residuo","RSU") -> 24810
C21: 6120JZX | D21: 1 | E21: Dia/Noche | F21: =GETPIVOTDATA("Carga",RSU!$A$1,"Matrícula","6120JZX","Residuo","RSU") -> 2340
C22: 7542KBV | D22: 2-3-4-5 | E22: Dia/Noche | F22: =GETPIVOTDATA("Carga",RSU!$A$1,"Matrícula","7542KBV","Residuo","RSU") -> 359290
C23: 1730KBZ | D23: 2-3-4-5 | E23: Noche | F23: =GETPIVOTDATA("Carga",RSU!$A$1,"Matrícula","1730KBZ","Residuo","RSU") -> 289000
C24: 1821KBZ | D24: 2-3-4-5 | E24: Noche | F24: =GETPIVOTDATA("Carga",RSU!$A$1,"Matrícula","1821KBZ","Residuo","RSU") -> 49080
C25: 0315BGK | D25: 2-3-4-5 | E25: Día/Noche | F25: =GETPIVOTDATA("Carga",RSU!$A$1,"Matrícula","0315BGK","Residuo","RSU") -> 2240
C26: 3686KBG | D26: 2-3-4-5 | E26: Dia | F26: =GETPIVOTDATA("Carga",RSU!$A$1,"Matrícula","3686KBG","Residuo","RSU") -> 9360 | I26: =SUM(F20:F26) -> 736120
B28: 2. Recogida de enseres y voluminosos
C30: Equipos utilizados | D30: Nº operarios | E30: Frecuencia/mensual | F30: Kg recogidos | G30: Incidencias
C31: 0315BGK | D31: 2 | E31: =GETPIVOTDATA("Fecha",RSU!$A$17,"Matrícula","0315BGK","Residuo","VOL") -> 1 | F31: =GETPIVOTDATA("Carga",RSU!$A$1,"Matrícula","0315BGK","Residuo","VOL") -> 5220 | G31: Todas las zonas
C32: 6120JZX | D32: 2 | E32: =GETPIVOTDATA("Fecha",RSU!$A$17,"Matrícula","6120JZX","Residuo","VOL") -> 23 | F32: =GETPIVOTDATA("Carga",RSU!$A$1,"Matrícula","6120JZX","Residuo","VOL") -> 14900 | G32: Todas las zonas
C33: 3686KBG | D33: 2 | E33: =GETPIVOTDATA("Fecha",RSU!$A$17,"Matrícula","3686KBG","Residuo","VOL") -> 2 | F33: =GETPIVOTDATA("Carga",RSU!$A$1,"Matrícula","3686KBG","Residuo","VOL") -> 480 | G33: Todas las zonas | I33: =SUM(F31:F33) -> 20600
B35: 3. Recogida selectiva de residuos
C37: Tipo de residuo | D37: Equipo utilizado | E37: Frecuencia/mensual | F37: Kg recogidos | G37: Incidencias
C39: Papel | D39: 0315BGK | E39: =GETPIVOTDATA("Fecha",RSU!$A$17,"Matrícula","0315BGK","Residuo","SEL.PAP") -> 1 | F39: =GETPIVOTDATA("Carga",RSU!$A$1,"Matrícula","0315BGK","Residuo","SEL.PAP") -> 4060
C40: Papel | D40: 1730KBZ | E40: =GETPIVOTDATA("Fecha",#REF!,"Matrícula","1730KBZ","Residuo","SEL.PAP") -> #REF! | F40: 0
C41: Papel | D41: 1821KBZ | E41: =GETPIVOTDATA("Fecha",RSU!$A$17,"Matrícula","1821KBZ","Residuo","SEL.PAP") -> 2 | F41: =GETPIVOTDATA("Carga",RSU!$A$1,"Matrícula","1821KBZ","Residuo","SEL.PAP") -> 3520
C42: Papel | D42: 1730KBZ | E42: =GETPIVOTDATA("Fecha",RSU!$A$17,"Matrícula","1730KBZ","Residuo","SEL.PAP") -> 1 | F42: =GETPIVOTDATA("Carga",RSU!$A$1,"Matrícula","1730KBZ","Residuo","SEL.PAP") -> 4980
C43: Envases | D43: 1730KBZ | E43: =GETPIVOTDATA("Fecha",RSU!$A$17,"Matrícula","1730KBZ","Residuo","SEL.ENV") -> 2 | F43: =GETPIVOTDATA("Carga",RSU!$A$1,"Matrícula","1730KBZ","Residuo","SEL.ENV") -> 5340
C44: Poda | D44: 0315BGK | E44: =GETPIVOTDATA("Fecha",RSU!$A$17,"Matrícula","0315BGK","Residuo","PODA") -> 4 | F44: =GETPIVOTDATA("Carga",RSU!$A$1,"Matrícula","0315BGK","Residuo","PODA") -> 18780
C45: Limpieza de playa | D45: 0315BGK | E45: =GETPIVOTDATA("Fecha",RSU!$A$17,"Matrícula","0315BGK","Residuo","LIMP. PLAY") -> 3 | F45: =GETPIVOTDATA("Carga",RSU!$A$1,"Matrícula","0315BGK","Residuo","LIMP. PLAY") -> 32400
C46: Papel | D46: 7957JZS | E46: =GETPIVOTDATA("Fecha",RSU!$A$17,"Matrícula","7957JZS","Residuo","SEL.PAP") -> 1 | F46: =GETPIVOTDATA("Carga",RSU!$A$1,"Matrícula","7957JZS","Residuo","SEL.PAP") -> 740 | I46: =SUM(F39:F46) -> 69820
C47: Poda | D47: 0315BGK | E47: =GETPIVOTDATA("Fecha",RSU!$A$17,"Matrícula","0315BGK","Residuo","PODA") -> 4 | F47: =GETPIVOTDATA("Carga",RSU!$A$1,"Matrícula","0315BGK","Residuo","PODA") -> 18780 | I47: =SUM(F39:F47) -> 88600
C48: Envases | D48: 1821KBZ | E48: =GETPIVOTDATA("Residuo",#REF!,"Matrícula","1821KBZ","Residuo","SEL.ENV") -> #REF! | F48: =GETPIVOTDATA("Carga",#REF!,"Matrícula","1821KBZ","Residuo","SEL.ENV") -> #REF!
C49: Papel | D49: 0315BGK | E49: =GETPIVOTDATA("Residuo",#REF!,"Matrícula","0315BGK","Residuo","SEL.PAP") -> #REF! | F49: =GETPIVOTDATA("Carga",#REF!,"Matrícula","0315BGK","Residuo","SEL.PAP") -> #REF! | I49: =SUM(F38:F49) -> #REF! | J49: =SUM(I26:I49) -> #REF!
I50: =I26+I33+I46 -> 826540
B51: 4. Contenedores. Mantenimiento y lavado
C53: Relación de operaciones de mantenimiento realizadas
D54: Reparación de contenedores carga trasera: 5 ud.
D55: Reparación de contenedores carga trasera hoteles: 1 ud.
D56: Reparación de contenedores carga lateral: 6 ud.
C58: Relación de operaciones de limpieza
C60: Equipo utilizado | D60: Tipo de contenedor/cantidad | E60: Frecuencia/mensual | F60: Incidencias
C62: CS6350AK | D62: Traseros / 280 | E62: 4
...

Sheet Pesadas octubre
A1: Fecha | B1: Fecha / hora | C1: Ticket | D1: Matrícula | E1: Peso total | F1: Tara | G1: Carga | H1: Población | I1: Residuo | J1: marca
A2: 43374 | B2: 0.058333333 | C2: 97772 | D2: 7542KBV | E2: 20840 | F2: 13040 | G2: 7800 | H2: Peñiscola | I2: RSU | J2: x
A3: 43374 | B3: 0.15069444 | C3: 97777 | D3: 7542KBV | E3: 18380 | F3: 12820 | G3: 5560 | H3: Peñiscola | I3: RSU | J3: x
A4: 43374 | B4: 0.24375 | C4: 97785 | D4: 7809JZX | E4: 4660 | F4: 3580 | G4: 1080 | H4: Peñiscola | I4: RSU | J4: x
A5: 43374 | B5: 0.24791667 | C5: 97786 | D5: 1821KBZ | E5: 24340 | F5: 15920 | G5: 8420 | H5: Peñiscola | I5: RSU | J5: x
A6: 43374 | B6: 0.45069444 | C6: 97798 | D6: 3686KBG | E6: 2580 | F6: 2380 | G6: 200 | H6: Peñiscola | I6: RSU | J6: x
A7: 43374 | B7: 0.51666667 | C7: 97802 | D7: 1730KBZ | E7: 17400 | F7: 15700 | G7: 1700 | H7: Peñiscola | I7: RSU | J7: x
A8: 43374 | B8: 0.68541667 | C8: 97813 | D8: 7542KBV | E8: 15080 | F8: 12900 | G8: 2180 | H8: Peñiscola | I8: RSU | J8: x
A9: 43374 | B9: 0.87986111 | C9: 97819 | D9: 1730KBZ | E9: 20900 | F9: 15780 | G9: 5120 | H9: Peñiscola | I9: RSU | J9: x
A10: 43375 | B10: 0.46805556 | C10: 78287 | D10: 1821KBZ | E10: 17680 | F10: 15720 | G10: 1960 | H10: Peñiscola | I10: SEL.PAP | J10: x
A11: 43375 | B11: 0.052083333 | C11: 97820 | D11: 7542KBV | E11: 20100 | F11: 12980 | G11: 7120 | H11: Peñiscola | I11: RSU | J11: x
A12: 43375 | B12: 0.21666667 | C12: 97827 | D12: 7809JZX | E12: 4480 | F12: 3720 | G12: 760 | H12: Peñiscola | I12: RSU | J12: x
A13: 43375 | B13: 0.23888889 | C13: 97829 | D13: 7542KBV | E13: 17020 | F13: 12800 | G13: 4220 | H13: Peñiscola | I13: RSU | J13: x
... A244: 43404 | B244: 0.44861111 | C244: 99104 | D244: 3686KBG | E244: 2620 | F244: 2380 | G244: 240 | H244: Peñiscola | I244: RSU | J244: x

Sheet Tabla dinámica_Pesadas octubre_1
A1: Matrícula | B1: - todo -
A3: Suma - Carga | B3: Residuo
A4: Fecha | B4: LIMP. PLAY | C4: PODA | D4: RSU | E4: SEL.ENV | F4: SEL.PAP | G4: VOL | H4: Total Resultado
A5: 43374 | D5: 32060 | H5: 32060
A6: 43375 | D6: 24100 | F6: 1960 | G6: 340 | H6: 26400
A7: 43376 | D7: 24980 | E7: 1400 | G7: 900 | H7: 27280
A8: 43377 | C8: 3980 | D8: 22800 | G8: 620 | H8: 27400
A9: 43378 | C9: 4520 | D9: 26880 | G9: 640 | H9: 32040
A10: 43379 | D10: 25620 | G10: 5700 | H10: 31320
A11: 43380 | D11: 25280 | H11: 25280
A12: 43381 | D12: 28050 | F12: 740 | G12: 820 | H12: 29610
A13: 43382 | D13: 24180 | G13: 860 | H13: 25040
A14: 43383 | D14: 24220 | H14: 24220
A15: 43384 | D15: 22220 | G15: 420 | H15: 22640
A16: 43385 | D16: 26100 | H16: 26100
A17: 43386 | D17: 33680 | G17: 720 | H17: 34400
A18: 43387 | D18: 33020 | H18: 33020
A19: 43388 | C19: 10280 | D19: 32320 | G19: 520 | H19: 43120
A20: 43389 | D20: 21940 | G20: 480 | H20: 22420
A21: 43390 | D21: 16940 | G21: 820 | H21: 17760
A22: 43391 | D22: 14320 | F22: 1560 | G22: 640 | H22: 16520
A23: 43392 | D23: 5340 | G23: 280 | H23: 5620
A24: 43393 | D24: 32520 | G24: 540 | H24: 33060
A25: 43394 | D25: 30020 | G25: 980 | H25: 31000
A26: 43395 | D26: 25720 | H26: 25720
A27: 43396 | B27: 9960 | D27: 19870 | H27: 29830
A28: 43397 | D28: 22480 | F28: 4060 | G28: 1400 | H28: 27940
A29: 43398 | B29: 22440 | D29: 21260 | G29: 940 | H29: 44640
A30: 43399 | D30: 19020 | G30: 780 | H30: 19800
A31: 43400 | D31: 23540 | G31: 780 | H31: 24320
A32: 43401 | D32: 10400 | H32: 10400
A33: 43402 | D33: 29000 | F33: 4980 | G33: 840 | H33: 34820
A34: 43403 | D34: 17740 | E34: 3940 | G34: 580 | H34: 22260
A35: 43404 | D35: 20500 | H35: 20500
A36: Total Resultado | B36: 32400 | C36: 18780 | D36: 736120 | E36: 5340 | F36: 13300 | G36: 20600 | H36: 826540

Sheet RSU
A1: Suma - Carga | B1: Residuo
A2: Matrícula | B2: LIMP. PLAY | C2: PODA | D2: RSU | E2: SEL.ENV | F2: SEL.PAP | G2: VOL | H2: (vacío) | I2: Total Resultado
A3: 0315BGK | B3: 32400 | C3: 18780 | D3: 2240 | F3: 4060 | G3: 5220 | I3: 62700
A4: 1730KBZ | D4: 289000 | E4: 5340 | F4: 4980 | I4: 299320
A5: 1821KBZ | D5: 49080 | F5: 3520 | I5: 52600
A6: 3686KBG | D6: 9360 | G6: 480 | I6: 9840
A7: 6120JZX | D7: 2340 | G7: 14900 | I7: 17240
A8: 7542KBV | D8: 359290 | I8: 359290
A9: 7809JZX | D9: 24810 | I9: 24810
A10: 7957JZS | F10: 740 | I10: 740
A11: (vacío)
A12: Total Resultado | B12: 32400 | C12: 18780 | D12: 736120 | E12: 5340 | F12: 13300 | G12: 20600 | I12: 826540
A17: Cantidad - Fecha | B17: Residuo
A18: Matrícula | B18: LIMP. PLAY | C18: PODA | D18: RSU | E18: SEL.ENV | F18: SEL.PAP | G18: VOL | H18: (vacío) | I18: Total Resultado
A19: 0315BGK | B19: 3 | C19: 4 | D19: 1 | F19: 1 | G19: 1 | I19: 10
A20: 1730KBZ | D20: 44 | E20: 2 | F20: 1 | I20: 47
A21: 1821KBZ | D21: 10 | F21: 2 | I21: 12
A22: 3686KBG | D22: 31 | G22: 2 | I22: 33
A23: 6120JZX | D23: 12 | G23: 23 | I23: 35
A24: 7542KBV | D24: 73 | I24: 73
A25: 7809JZX | D25: 32 | I25: 32
A26: 7957JZS | F26: 1 | I26: 1
A27: (vacío)
A28: Total Resultado | B28: 3 | C28: 4 | D28: 203 | E28: 2 | F28: 5 | G28: 26 | I28: 243

Sheet Vehiculos
A1: Nº Veh. | B1: Matrícula | C1: Marca y Modelo | E1: F. Matric | F1: Empresa | G1: Dpto. | H1: Cat. SAP | I1: Centro Coste | J1: Descripción
A2: 3628 | B2: 2210DZV | C2: Lavacontenedores lateral
A3: 0059 | B3: CS42174VE | C3: Cherrington Limpia Playas | E3: 35299 | F3: 3000 | G3: 7008 | H3: V0158 | I3: 0300010278 | J3: Peñiscola LV Explotacion
A4: 0065 | B4: CS7675AJ | C4: Scania 93 ML 6x2 A | E4: 35282 | F4: 3000 | G4: 7008 | H4: V0018 | I4: 0300010267 | J4: Peñiscola RSU Recogida
A5: 0079 | B5: SRAKE79 | C5: Barber Surf Rake 600 HD | E5: 36526 | F5: 3000 | G5: 7008 | H5: V0182 | I5: 0300010278 | J5: Peñiscola LV Explotacion
A6: 0089 | B6: CS44377VE | C6: Bucher CityCat 2000 | E6: 36272 | F6: 3000 | G6: 7008 | H6: V0030 | I6: 0300010278 | J6: Peñiscola LV Explotacion
A7: 0095 | B7: CS1637AW | C7: Iveco MH190E27 / P | E7: 36711 | F7: 3000 | G7: 7008 | H7: V0032 | I7: 0300010267 | J7: Peñiscola RSU Recogida
A8: 0104 | B8: 7173BGH | C8: Nissan Cabstar E 110.35 | E8: 36963 | F8: 3000 | G8: 7008 | H8: V0038 | I8: 0300010278 | J8: Peñiscola LV Explotacion
A9: 0115 | B9: E6483BBS | C9: John Deere 6910 (103KW) | E9: 37127 | F9: 3000 | G9: 7008 | H9: V0048 | I9: 0300010278 | J9: Peñiscola LV Explotacion
A10: 0119 | B10: 0587BPB | C10: Land Rover Defender 130 | E10: 37193 | F10: 3000 | G10: 7008 | H10: V0049 | I10: 0300010278 | J10: Peñiscola LV Explotacion
A11: 0128 | B11: 9825BYG | C11: Land Rover Defender 130 | E11: 37460 | F11: 3000 | G11: 7008 | H11: V0055 | I11: 0300010278 | J11: Peñiscola LV Explotacion
A12: 0145 | B12: C0720BRB | C12: Honda SZX50X | E12: 38203 | F12: 3000 | G12: 7008 | H12: V0164 | I12: 0300010278 | J12: Peñiscola LV Explotacion
A13: 0152 | B13: E9358BDD | C13: Kassbohrer Beach Tech STR 3000 | E13: 38533 | F13: 3000 | G13: 7008 | H13: V0068 | I13: 0300010278 | J13: Peñiscola LV Explotacion
A14: 0153 | B14: E0424BDF | C14: John Deere 6820 | E14: 38538 | F14: 3000 | G14: 7008 | H14: V0069 | I14: 0300010278 | J14: Peñiscola LV Explotacion
... A54: 6011 | B54: R9813BCF | C54: MURSEM CAJA CERRADA | E54: 39594 | F54: 3000 | G54: 7008 | H54: V0226 | I54: 0300010296 | J54: Peñiscola Transporte Residuos Peñiscola

Sheet Hoja5
B1: RSU | C1: certificado | D1: comprobado
A3: 109 | B3: 0315BGK | C3: 2240 | D3: 2240
A4: 320 | B4: 1730KBZ | C4: 289000 | D4: 289000
A5: 321 | B5: 1821KBZ | C5: 49080 | D5: 49080
A6: 316 | B6: 3686KBG | C6: 9360 | D6: 9360
A7: 196 | B7: 5313GBZ
A8: 309 | B8: 6120JZX | C8: 2340 | D8: 2340
A9: 104 | B9: 7173BGH
A10: 318 | B10: 7542KBV | C10: 359290 | D10: 359290
A11: 170 | B11: 7777FCX
A12: 310 | B12: 7809JZX | C12: 24810 | D12: 24810
B14: VOLUMINOSOS
A15: 109 | B15: 0315BGK | C15: 5220 | D15: 5220
A16: 309 | B16: 6120JZX | C16: 14900 | D16: 14900
A17: 316 | B17: 3686KBG | C17: 480 | D17: 480
B19: SELECTIVA
B20: PAPEL | I20: 0
A21: 109 | B21: 0315BGK | C21: 4060 | D21: 4060
A22: 320 | B22: 1730KBZ | C22: 4980 | D22: 4980
A23: 321 | B23: 1821KBZ | C23: 3520 | D23: 3520
A24: 296 | B24: 7957JZS | C24: 740 | D24: 740
B25: ENVASES
A26: 109 | B26: 0315BGK
A27: 320 | B27: 1730KBZ | C27: 5340 | D27: 5340
A28: 321 | B28: 1821KBZ
B30: PLAYAS
A31: 109 | B31: 0315BGK | C31: 32400 | D31: 32400
B32: PODA
A33: 104 | B33: 7173BGH
A34: 109 | B34: 0315BGK | C34: 18780 | D34: 18780
C35: =SUM(C3:C34) -> 826540 | D35: =SUM(D3:D34) -> 826540
