Workbook

Sheet Hoja1
A1: Fecha | B1: Fecha / hora | C1: Ticket | D1: Matrícula | E1: Peso total | F1: Tara | G1: Carga | H1: Población | I1: Residuo | J1: revisado
A2: 43678 | B2: 0.050694444 | C2: 111637 | D2: 7542KBV | E2: 22440 | F2: 13040 | G2: 9400 | H2: Peñiscola | I2: RSU | J2: x
A3: 43678 | B3: 0.13819444 | C3: 111643 | D3: 1730KBZ | E3: 25380 | F3: 15820 | G3: 9560 | H3: Peñiscola | I3: RSU | J3: x
A4: 43678 | B4: 0.14166667 | C4: 111645 | D4: 7542KBV | E4: 19800 | F4: 13020 | G4: 6780 | H4: Peñiscola | I4: RSU | J4: x
A5: 43678 | B5: 0.16666667 | C5: 111647 | D5: 7809JZX | E5: 4800 | F5: 3600 | G5: 1200 | H5: Peñiscola | I5: RSU | J5: x
A6: 43678 | B6: 0.23611111 | C6: 111651 | D6: 7542KBV | E6: 17360 | F6: 12840 | G6: 4520 | H6: Peñiscola | I6: RSU | J6: x
A7: 43678 | B7: 0.24027778 | C7: 111652 | D7: 1730KBZ | E7: 21420 | F7: 15780 | G7: 5640 | H7: Peñiscola | I7: RSU | J7: x
A8: 43678 | B8: 0.24513889 | C8: 111653 | D8: 7809JZX | E8: 4600 | F8: 3740 | G8: 860 | H8: Peñiscola | I8: RSU | J8: x
A9: 43678 | B9: 0.45972222 | C9: 111675 | D9: 6120JZX | E9: 3380 | F9: 2880 | G9: 500 | H9: Peñiscola | I9: RSU | J9: x
A10: 43678 | B10: 0.39375 | C10: 111669 | D10: 7957JZS | E10: 5820 | F10: 5560 | G10: 260 | H10: Peñiscola | I10: VOL | J10: x
A11: 43678 | B11: 0.68958333 | C11: 111693 | D11: 7542KBV | E11: 15880 | F11: 12800 | G11: 3080 | H11: Peñiscola | I11: RSU | J11: x
A12: 43678 | B12: 0.74375 | C12: 111698 | D12: 1076KSZ | E12: 3020 | F12: 2760 | G12: 260 | H12: Peñiscola | I12: RSU | J12: x
A13: 43678 | B13: 0.87638889 | C13: 111702 | D13: 6120JZX | E13: 3200 | F13: 3040 | G13: 160 | H13: Peñiscola | I13: RSU | J13: x
... A29: 43679 | B29: 0.91736111 | C29: 111773 | D29: 6120JZX | E29: 3340 | F29: 3040 | G29: 300 | H29: Peñiscola | I29: RSU | J29: x
A30: 43679 | B30: 0.44097222 | C30: TETMA | D30: 1821KBZ | E30: 18760 | F30: 15760 | G30: 3000 | H30: Peñiscola | I30: SEL.ENV | J30: x
A31: 43680 | B31: 0.45486111 | C31: 90999 | D31: 1821KBZ | E31: 18320 | F31: 15880 | G31: 2440 | H31: Peñiscola | I31: SEL.PAP | J31: x
A32: 43680 | B32: 0.040277778 | C32: 111775 | D32: 7542KBV | E32: 21800 | F32: 13080 | G32: 8720 | H32: Peñiscola | I32: RSU | J32: x
A33: 43680 | B33: 0.12638889 | C33: 111782 | D33: 1821KBZ | E33: 26140 | F33: 15940 | G33: 10200 | H33: Peñiscola | I33: RSU | J33: x
A34: 43680 | B34: 0.13402778 | C34: 111783 | D34: 6120JZX | E34: 3000 | F34: 2740 | G34: 260 | H34: Peñiscola | I34: RSU | J34: x
A35: 43680 | B35: 0.15972222 | C35: 111785 | D35: 7542KBV | E35: 22340 | F35: 12860 | G35: 9480 | H35: Peñiscola | I35: RSU | J35: x
A36: 43680 | B36: 0.16597222 | C36: 111786 | D36: 7809JZX | E36: 4840 | F36: 3600 | G36: 1240 | H36: Peñiscola | I36: RSU | J36: x
A37: 43680 | B37: 0.44861111 | C37: 111809 | D37: 6120JZX | E37: 3360 | F37: 2860 | G37: 500 | H37: Peñiscola | I37: VOL | J37: x
A38: 43680 | B38: 0.20069444 | C38: 111788 | D38: 1730KBZ | E38: 27180 | F38: 15870 | G38: 11310 | H38: Peñiscola | I38: RSU | J38: x
A39: 43680 | B39: 0.23472222 | C39: 111792 | D39: 7542KBV | E39: 14600 | F39: 12780 | G39: 1820 | H39: Peñiscola | I39: RSU | J39: x
A40: 43680 | B40: 0.25 | C40: 111794 | D40: 7809JZX | E40: 4800 | F40: 3800 | G40: 1000 | H40: Peñiscola | I40: RSU | J40: x
A41: 43680 | B41: 0.32222222 | C41: 111802 | D41: 6120JZX | E41: 3220 | F41: 2880 | G41: 340 | H41: Peñiscola | I41: RSU | J41: x
A42: 43680 | B42: 0.69444444 | C42: 111816 | D42: 7542KBV | E42: 15940 | F42: 12840 | G42: 3100 | H42: Peñiscola | I42: RSU | J42: x
... A67: 43682 | B67: 0.22430556 | C67: 111866 | D67: 7809JZX | E67: 4540 | F67: 3720 | G67: 820 | H67: Peñiscola | I67: RSU | J67: x
A68: 43682 | B68: 0.45486111 | C68: TETMA | D68: 1821KBZ | E68: 18400 | F68: 15760 | G68: 2640 | H68: Peñiscola | I68: SEL.ENV | J68: x
A69: 43682 | B69: 0.23611111 | C69: 111867 | D69: 7542KBV | E69: 15280 | F69: 12700 | G69: 2580 | H69: Peñiscola | I69: RSU | J69: x
A70: 43682 | B70: 0.33888889 | C70: 111879 | D70: 6120JZX | E70: 3700 | F70: 2880 | G70: 820 | H70: Peñiscola | I70: VOL | J70: x
A71: 43682 | B71: 0.45902778 | C71: 111893 | D71: 6120JZX | E71: 3380 | F71: 2880 | G71: 500 | H71: Peñiscola | I71: RSU | J71: x
A72: 43682 | B72: 0.75138889 | C72: 111911 | D72: 1076KSZ | E72: 2920 | F72: 2780 | G72: 140 | H72: Peñiscola | I72: RSU | J72: x
A73: 43682 | B73: 0.88472222 | C73: 111912 | D73: 6120JZX | E73: 3200 | F73: 3020 | G73: 180 | H73: Peñiscola | I73: RSU | J73: x
A74: 43682 | B74: 0.89652778 | C74: 111913 | D74: 1821KBZ | E74: 26300 | F74: 15960 | G74: 10340 | H74: Peñiscola | I74: RSU | J74: x
A75: 43683 | B75: 0.04375 | C75: 111914 | D75: 7542KBV | E75: 21340 | F75: 13100 | G75: 8240 | H75: Peñiscola | I75: RSU | J75: x
A76: 43683 | B76: 0.13888889 | C76: 111921 | D76: 1076KSZ | E76: 3020 | F76: 2800 | G76: 220 | H76: Peñiscola | I76: RSU | J76: x
A77: 43683 | B77: 0.14027778 | C77: 111922 | D77: 7542KBV | E77: 21100 | F77: 12920 | G77: 8180 | H77: Peñiscola | I77: RSU | J77: x
A78: 43683 | B78: 0.15347222 | C78: 111924 | D78: 1821KBZ | E78: 26500 | F78: 16060 | G78: 10440 | H78: Peñiscola | I78: RSU | J78: x
A79: 43683 | B79: 0.15972222 | C79: 111925 | D79: 7809JZX | E79: 4900 | F79: 3580 | G79: 1320 | H79: Peñiscola | I79: RSU | J79: x
...

Sheet TIPO RESIDUOS
A1: Fecha | B1: - todo -
A3: Suma - Carga | B3: Residuo
A4: Matrícula | B4: LIMP.PLAYA | C4: PODA | D4: RSU | E4: SEL.ENV | F4: SEL.PAP | G4: VOL | H4: Total Resultado
A5: 0315BGK | B5: 10280 | D5: 6020 | F5: 5320 | H5: 21620
A6: 1076KSZ | C6: 600 | D6: 25860 | G6: 1620 | H6: 28080
A7: 1730KBZ | D7: 666610 | E7: 5160 | F7: 1920 | H7: 673690
A8: 1821KBZ | D8: 282620 | E8: 24900 | F8: 18240 | H8: 325760
A9: 3686KBG | D9: 6290 | H9: 6290
A10: 5313GBZ | D10: 2500 | H10: 2500
A11: 6120JZX | D11: 27660 | G11: 10340 | H11: 38000
A12: 7542KBV | D12: 879340 | H12: 879340
A13: 7809JZX | D13: 58280 | H13: 58280
A14: 7957JZS | F14: 1500 | G14: 1720 | H14: 3220
A15: Total Resultado | B15: 10280 | C15: 600 | D15: 1955180 | E15: 30060 | F15: 26980 | G15: 13680 | H15: 2036780

Sheet certificacion
A1: RSU
A2: MATRICULA | B2: RUTA | C2: HORARIO | D2: CARGA | E2: REVISADO
A3: 7809JZX | B3: 1 | C3: Noche | D3: 58280 | E3: =VLOOKUP(A3,'TIPO RESIDUOS'!$A$4:$H$15,4) -> 58280 | F3: =IF(E3-D3>0,"Revisar","Bien") -> Bien
A4: 6120JZX | B4: 1 | C4: Dia/Noche | D4: 27660 | E4: =VLOOKUP(A4,'TIPO RESIDUOS'!$A$4:$H$15,4) -> 27660 | F4: =IF(E4-D4>0,"Revisar","Bien") -> Bien
A5: 7542KBV | B5: 2-3-4-5 | C5: Dia/Noche | D5: 879340 | E5: =VLOOKUP(A5,'TIPO RESIDUOS'!$A$4:$H$15,4) -> 879340 | F5: =IF(E5-D5>0,"Revisar","Bien") -> Bien
A6: 1730KBZ | B6: 2-3-4-5 | C6: Dia/Noche | D6: 666610 | E6: =VLOOKUP(A6,'TIPO RESIDUOS'!$A$4:$H$15,4) -> 666610 | F6: =IF(E6-D6>0,"Revisar","Bien") -> Bien
A7: 1821KBZ | B7: 2-3-4-5 | C7: Dia/Noche | D7: 282620 | E7: =VLOOKUP(A7,'TIPO RESIDUOS'!$A$4:$H$15,4) -> 282620 | F7: =IF(E7-D7>0,"Revisar","Bien") -> Bien
A8: 5313GBZ | B8: 2-3-4-5 | C8: Día/Noche | D8: 2500 | E8: =VLOOKUP(A8,'TIPO RESIDUOS'!$A$4:$H$15,4) -> 2500 | F8: =IF(E8-D8>0,"Revisar","Bien") -> Bien
A9: 3686KBG | B9: 2-3-4-5 | C9: Dia | D9: 6290 | E9: =VLOOKUP(A9,'TIPO RESIDUOS'!$A$4:$H$15,4) -> 6290 | F9: =IF(E9-D9>0,"Revisar","Bien") -> Bien
A10: 0315BGK | B10: 2-3-4-5 | C10: Día | D10: 6020 | E10: =VLOOKUP(A10,'TIPO RESIDUOS'!$A$4:$H$15,4) -> 6020 | F10: =IF(E10-D10>0,"Revisar","Bien") -> Bien
A11: 1076KSZ | B11: 1 | C11: Noche | D11: 25860 | E11: =VLOOKUP(A11,'TIPO RESIDUOS'!$A$4:$H$15,4) -> 25860 | F11: =IF(E11-D11>0,"Revisar","Bien") -> Bien
E12: =SUM(E3:E11) -> 1955180
A13: VOLUMINOSOS
A14: MATRICULA | B14: N.º OPERARIOS | C14: FRECUENCIA | D14: CARGA | E14: REVISADO
A15: 1076KSZ | B15: 2 | C15: 2 | D15: 1620 | E15: =VLOOKUP(A15,'TIPO RESIDUOS'!$A$4:$H$15,7) -> 1620 | F15: =IF(E15-D15>0,"Revisar","Bien") -> Bien
A16: 6120JZX | B16: 2 | C16: 22 | D16: 10340 | E16: =VLOOKUP(A16,'TIPO RESIDUOS'!$A$4:$H$15,7) -> 10340 | F16: =IF(E16-D16>0,"Revisar","Bien") -> Bien
A17: 7957JZS | B17: 2 | C17: 3 | D17: 1720 | E17: =VLOOKUP(A17,'TIPO RESIDUOS'!$A$4:$H$15,7) -> 1720 | F17: =IF(E17-D17>0,"Revisar","Bien") -> Bien
E18: =SUM(E15:E17) -> 13680
A19: PAPEL
A20: MATRICULA | B20: FRECUENCIA | C20: CARGA | D20: REVISADO
A21: 0315BGK | B21: 3 | C21: 5320 | D21: =VLOOKUP(A21,'TIPO RESIDUOS'!$A$4:$H$15,6) -> 5320 | E21: =IF(D21-C21>0,"Revisar","Bien") -> Bien
A22: 1821KBZ | B22: 9 | C22: 18240 | D22: =VLOOKUP(A22,'TIPO RESIDUOS'!$A$4:$H$15,6) -> 18240 | E22: =IF(D22-C22>0,"Revisar","Bien") -> Bien
A23: 7957JZS | B23: 2 | C23: 1500 | D23: =VLOOKUP(A23,'TIPO RESIDUOS'!$A$4:$H$15,6) -> 1500 | E23: =IF(D23-C23>0,"Revisar","Bien") -> Bien
A24: 1730KBZ | B24: 1 | C24: 1920 | D24: =VLOOKUP(A24,'TIPO RESIDUOS'!$A$4:$H$15,6) -> 1920 | E24: =IF(D24-C24>0,"Revisar","Bien") -> Bien
D25: =SUM(D21:D24) -> 26980
A26: ENVASES
A27: MATRICULA | B27: FRECUENCIA | C27: CARGA | D27: REVISADO
A28: 1730KBZ | B28: 1 | C28: 5160 | D28: =VLOOKUP(A28,'TIPO RESIDUOS'!$A$4:$H$15,5) -> 5160 | E28: =IF(D28-C28>0,"Revisar","Bien") -> Bien
A29: 1821KBZ | B29: 8 | C29: 24900 | D29: =VLOOKUP(A29,'TIPO RESIDUOS'!$A$4:$H$15,5) -> 24900 | E29: =IF(D29-C29>0,"Revisar","Bien") -> Bien
D30: =SUM(D28:D29) -> 30060
A31: PODA
A32: MATRICULA | B32: FRECUENCIA | C32: CARGA | D32: REVISADO
A33: 1076KSZ | B33: 2 | C33: 600 | D33: =VLOOKUP(A33,'TIPO RESIDUOS'!$A$4:$H$15,3) -> 600 | E33: =IF(D33-C33>0,"Revisar","Bien") -> Bien
D34: =SUM(D33:D33) -> 600
A35: PLAYAS
A36: MATRICULA | B36: FRECUENCIA | C36: CARGA | D36: REVISADO
A37: 0315BGK | B37: 2 | C37: 10280 | D37: =VLOOKUP(A37,'TIPO RESIDUOS'!$A$4:$H$15,2) -> 10280 | E37: =IF(D37-C37>0,"Revisar","Bien") -> Bien
D38: =SUM(D37:D37) -> 10280
D41: =+E12+E18+D25+D30+D34+D38 -> 2036780

Sheet Tabla dinámica_Hoja1_1
A1: Residuo | B1: - todo -
A3: Suma - Carga | B3: Matrícula
A4: Fecha | B4: 0315BGK | C4: 1076KSZ | D4: 1730KBZ | E4: 1821KBZ | F4: 3686KBG | G4: 5313GBZ | H4: 6120JZX | I4: 7542KBV | J4: 7809JZX | K4: 7957JZS | L4: Total Resultado
A5: 43678 | C5: 260 | D5: 24120 | H5: 660 | I5: 23780 | J5: 2060 | K5: 260 | L5: 51140
A6: 43679 | B6: 3340 | C6: 260 | D6: 19080 | E6: 12680 | H6: 1360 | I6: 24820 | J6: 2080 | L6: 63620
A7: 43680 | C7: 220 | D7: 22570 | E7: 12640 | H7: 1420 | I7: 23120 | J7: 2240 | L7: 62210
A8: 43681 | C8: 3020 | D8: 26840 | H8: 940 | I8: 29020 | L8: 59820
A9: 43682 | C9: 140 | D9: 11020 | E9: 25400 | H9: 1920 | I9: 24880 | J9: 2160 | L9: 65520
A10: 43683 | C10: 420 | E10: 29100 | H10: 1200 | I10: 24580 | J10: 2180 | L10: 57480
A11: 43684 | C11: 540 | D11: 22100 | E11: 11900 | H11: 1740 | I11: 26260 | J11: 2440 | L11: 64980
A12: 43685 | C12: 2820 | D12: 21280 | H12: 680 | I12: 23360 | L12: 48140
A13: 43686 | C13: 200 | D13: 28620 | E13: 12340 | H13: 2200 | I13: 31540 | J13: 2500 | L13: 77400
A14: 43687 | C14: 260 | D14: 11600 | E14: 28280 | H14: 1300 | I14: 30860 | J14: 2720 | K14: 500 | L14: 75520
A15: 43688 | C15: 220 | D15: 21540 | E15: 10720 | H15: 1200 | I15: 31000 | J15: 3180 | L15: 67860
A16: 43689 | B16: 1920 | C16: 2780 | D16: 11700 | E16: 26700 | H16: 1340 | I16: 30480 | L16: 74920
A17: 43690 | B17: 3180 | C17: 260 | D17: 24540 | E17: 7420 | H17: 1260 | I17: 27380 | J17: 2500 | L17: 66540
A18: 43691 | C18: 220 | D18: 31800 | H18: 1140 | I18: 29960 | J18: 2760 | K18: 1460 | L18: 67340
A19: 43692 | C19: 200 | D19: 30460 | E19: 1880 | H19: 1060 | I19: 27080 | J19: 2740 | L19: 63420
A20: 43693 | B20: 1700 | C20: 2020 | D20: 23800 | E20: 13940 | H20: 900 | I20: 32920 | J20: 1320 | L20: 76600
A21: 43694 | C21: 360 | D21: 23320 | E21: 13720 | H21: 1420 | I21: 31420 | J21: 2920 | L21: 73160
A22: 43695 | C22: 540 | D22: 32740 | H22: 920 | I22: 30580 | J22: 3260 | L22: 68040
A23: 43696 | C23: 380 | D23: 19640 | E23: 14900 | H23: 2180 | I23: 32700 | J23: 2420 | L23: 72220
A24: 43697 | B24: 2840 | C24: 1700 | D24: 20080 | E24: 10800 | H24: 1000 | I24: 27840 | J24: 580 | L24: 64840
A25: 43698 | C25: 1200 | D25: 22460 | E25: 10660 | H25: 1820 | I25: 32320 | J25: 2600 | L25: 71060
A26: 43699 | D26: 28340 | E26: 1720 | F26: 520 | H26: 920 | I26: 26420 | J26: 2360 | L26: 60280
A27: 43700 | B27: 1700 | C27: 360 | D27: 21740 | E27: 13040 | F27: 530 | H27: 2140 | I27: 33840 | J27: 2380 | L27: 75730
A28: 43701 | C28: 2460 | D28: 20900 | E28: 13160 | F28: 560 | H28: 1040 | I28: 31760 | L28: 69880
A29: 43702 | D29: 30780 | F29: 1400 | H29: 900 | I29: 29240 | J29: 2900 | L29: 65220
A30: 43703 | C30: 680 | D30: 21300 | E30: 13380 | F30: 280 | H30: 1280 | I30: 29400 | J30: 2180 | L30: 68500
A31: 43704 | B31: 6940 | C31: 1180 | D31: 19060 | E31: 8960 | F31: 680 | I31: 23260 | J31: 1840 | L31: 61920
A32: 43705 | C32: 3460 | D32: 19220 | E32: 8700 | F32: 820 | G32: 2500 | I32: 27720 | L32: 62420
A33: 43706 | C33: 1680 | D33: 24100 | E33: 1680 | F33: 480 | H33: 1340 | I33: 26260 | K33: 1000 | L33: 56540
A34: 43707 | C34: 240 | D34: 20300 | E34: 11500 | F34: 500 | H34: 1340 | I34: 28880 | J34: 2060 | L34: 64820
A35: 43708 | D35: 18640 | E35: 10540 | F35: 520 | H35: 1380 | I35: 26660 | J35: 1900 | L35: 59640
A36: Total Resultado | B36: 21620 | C36: 28080 | D36: 673690 | E36: 325760 | F36: 6290 | G36: 2500 | H36: 38000 | I36: 879340 | J36: 58280 | K36: 3220 | L36: 2036780
